try{
let a=0;
console.log(program)
console.log('program ran successfully')
}
catch(err){
console.log('This is an error')
console.log(p)
}
//! finally will run any case
//!if any error present in catch  or any return in try then olso finally runs
finally{
    console.log('i am finally')
}